Workbook

Sheet Premissas
A1: 12500
A2: Aba 1 — Premissas | Valores em R$ mil, salvo indicação
A4: 1. BASE OPERACIONAL
A5: EBITDA base (3T25 LTM) | C5: 2190000 | D5: Input
A6: Margem EBITDA histórica (média 2022-2025) | C6: 0.277 | D6: Input
A7: Receita base implícita (Ano 0) | C7: =C5/C6 -> 7906137.2 | D7: EBITDA base / margem histórica
A9: 2. PREMISSAS DE TRANSAÇÃO
A10: Múltiplo de entrada (EV/EBITDA) | C10: 6.25 | D10: Input
A11: Múltiplo de saída (caso base) | C11: 6.25 | D11: Input
A12: Dívida líquida existente (ex-arrendamento) — a refinanciar | C12: 1630000 | D12: Input
A13: Alavancagem inicial pós-transação (Dív. Nova / EBITDA) | C13: 4.5 | D13: Input
A14: Taxas de transação (% do Enterprise Value) | C14: 0.02 | D14: Input
A16: 3. FINANCIAMENTO
A17: CDI (a.a.) | C17: 0.12 | D17: Input editável
A18: Spread da dívida nova (a.a.) | C18: 0.02 | D18: Input
A19: Custo total da dívida nova (a.a.) | C19: =C17+C18 -> 0.14 | D19: CDI + spread
A20: % do caixa excedente destinado ao cash sweep | C20: 1 | D20: Input
A22: 4. PREMISSAS DE PROJEÇÃO (5 ANOS)
A23: Horizonte de investimento (anos) | C23: 5 | D23: Input
A24: Crescimento de receita (a.a.) | C24: 0.08 | D24: Conservador vs. histórico de 23,9% (inflado por M&A)
A25: Margem EBITDA projetada | C25: 0.275 | D25: Mantida constante nos 5 anos
A26: Capex (% da receita) | C26: 0.07 | D26: Média histórica
A27: Variação de capital de giro (% da Δ receita) | C27: 0.02 | D27: Input
A28: Depreciação & amortização (% da receita) | C28: 0.04 | D28: Input
A29: Alíquota efetiva de imposto de renda | C29: 0.34 | D29: Input
A31: 5. ARRENDAMENTO (IFRS 16) — FORA DA DÍVIDA DE AQUISIÇÃO
A32: Passivo de arrendamento (saldo inicial) | C32: 1250000 | D32: Input
A33: Pagamento anual (% do saldo de abertura) | C33: 0.15 | D33: Input

Sheet Sources & Uses
A1: FLEURY S.A. (FLRY3) — ABA 2: SOURCES & USES
A2: Valores em R$ mil | Verde = link para outra aba
A4: A. AVALIAÇÃO DE ENTRADA
A5: EBITDA base (3T25 LTM) | C5: =Premissas!C5 -> 2190000
A6: Múltiplo de entrada (EV/EBITDA) | C6: =Premissas!C10 -> 6.25
A7: Enterprise Value de entrada | C7: =C5*C6 -> 13687500
A8: (−) Dívida líquida existente | C8: =Premissas!C12 -> 1630000
A9: Equity Value a pagar aos acionistas | C9: =C7-C8 -> 12057500
A11: B. USOS DE RECURSOS
A12: Compra do equity | C12: =C9 -> 12057500
A13: Refinanciamento da dívida existente | C13: =C8 -> 1630000
A14: Taxas de transação | C14: =C7*Premissas!C14 -> 273750
A15: TOTAL DE USOS | C15: =SUM(C12:C14) -> 13961250
A17: C. FONTES DE RECURSOS
A18: Dívida nova (alavancagem × EBITDA) | C18: =Premissas!C13*Premissas!C5 -> 9855000
A19: Equity do sponsor (plug) | C19: =C15-C18 -> 4106250
A20: TOTAL DE FONTES | C20: =SUM(C18:C19) -> 13961250
A22: D. CHECAGENS
A23: Fontes − Usos (deve ser zero) | C23: =C20-C15 -> 0
A24: Alavancagem implícita (Dív. Nova / EBITDA) | C24: =C18/C5 -> 4.5
A25: Equity como % do total de fontes | C25: =C19/C20 -> 0.29411765

Sheet Projeções
A1: FLEURY S.A. (FLRY3) — ABA 3: PROJEÇÕES OPERACIONAIS
A2: Valores em R$ mil | Todas as premissas puxadas da Aba 1
A4: Demonstrativo projetado | C4: Ano 0 | D4: Ano 1 | E4: Ano 2 | F4: Ano 3 | G4: Ano 4 | H4: Ano 5
A5: RECEITA E EBITDA
A6: Receita líquida | C6: =Premissas!C7 -> 7906137.2 | D6: =C6*(1+Premissas!$C$24) -> 8538628.2 | E6: =D6*(1+Premissas!$C$24) -> 9221718.4 | F6: =E6*(1+Premissas!$C$24) -> 9959455.9 | G6: =F6*(1+Premissas!$C$24) -> 10756212 | H6: =G6*(1+Premissas!$C$24) -> 11616709
A7: Crescimento (%) | D7: =D6/C6-1 -> 0.08 | E7: =E6/D6-1 -> 0.08 | F7: =F6/E6-1 -> 0.08 | G7: =G6/F6-1 -> 0.08 | H7: =H6/G6-1 -> 0.08
A8: EBITDA | C8: =Premissas!C5 -> 2190000 | D8: =D6*Premissas!$C$25 -> 2348122.7 | E8: =E6*Premissas!$C$25 -> 2535972.6 | F8: =F6*Premissas!$C$25 -> 2738850.4 | G8: =G6*Premissas!$C$25 -> 2957958.4 | H8: =H6*Premissas!$C$25 -> 3194595.1
A9: Margem EBITDA (%) | C9: =C8/C6 -> 0.277 | D9: =D8/D6 -> 0.275 | E9: =E8/E6 -> 0.275 | F9: =F8/F6 -> 0.275 | G9: =G8/G6 -> 0.275 | H9: =H8/H6 -> 0.275
A10: (−) Depreciação & amortização | D10: =-D6*Premissas!$C$28 -> -341545.13 | E10: =-E6*Premissas!$C$28 -> -368868.74 | F10: =-F6*Premissas!$C$28 -> -398378.24 | G10: =-G6*Premissas!$C$28 -> -430248.49 | H10: =-H6*Premissas!$C$28 -> -464668.37
A11: EBIT | D11: =D8+D10 -> 2006577.6 | E11: =E8+E10 -> 2167103.8 | F11: =F8+F10 -> 2340472.1 | G11: =G8+G10 -> 2527709.9 | H11: =H8+H10 -> 2729926.7
A13: ITENS DE CAIXA
A14: Capex | D14: =-D6*Premissas!$C$26 -> -597703.97 | E14: =-E6*Premissas!$C$26 -> -645520.29 | F14: =-F6*Premissas!$C$26 -> -697161.91 | G14: =-G6*Premissas!$C$26 -> -752934.86 | H14: =-H6*Premissas!$C$26 -> -813169.65
A15: Δ Receita vs. ano anterior | D15: =D6-C6 -> 632490.97 | E15: =E6-D6 -> 683090.25 | F15: =F6-E6 -> 737737.47 | G15: =G6-F6 -> 796756.47 | H15: =H6-G6 -> 860496.99
A16: Variação de capital de giro (saída de caixa) | D16: =-D15*Premissas!$C$27 -> -12649.819 | E16: =-E15*Premissas!$C$27 -> -13661.805 | F16: =-F15*Premissas!$C$27 -> -14754.749 | G16: =-G15*Premissas!$C$27 -> -15935.129 | H16: =-H15*Premissas!$C$27 -> -17209.94
A18: ARRENDAMENTO (IFRS 16)
A19: Saldo inicial do arrendamento | D19: =Premissas!C32 -> 1250000 | E19: =D21 -> 1062500 | F19: =E21 -> 903125 | G19: =F21 -> 767656.25 | H19: =G21 -> 652507.81
A20: Pagamento anual de arrendamento | D20: =-D19*Premissas!$C$33 -> -187500 | E20: =-E19*Premissas!$C$33 -> -159375 | F20: =-F19*Premissas!$C$33 -> -135468.75 | G20: =-G19*Premissas!$C$33 -> -115148.44 | H20: =-H19*Premissas!$C$33 -> -97876.172
A21: Saldo final do arrendamento | D21: =D19+D20 -> 1062500 | E21: =E19+E20 -> 903125 | F21: =F19+F20 -> 767656.25 | G21: =G19+G20 -> 652507.81 | H21: =H19+H20 -> 554631.64

Sheet Debt Schedule
A1: FLEURY S.A. (FLRY3) — ABA 4: DEBT SCHEDULE E CASH SWEEP
A2: Valores em R$ mil | Juros sobre SALDO MÉDIO — requer cálculo iterativo (já habilitado)
A4: Cascata de dívida | D4: Ano 1 | E4: Ano 2 | F4: Ano 3 | G4: Ano 4 | H4: Ano 5
A5: IMPOSTO DE RENDA
A6: EBIT (Aba 3) | D6: =Projeções!D11 -> 2006577.6 | E6: =Projeções!E11 -> 2167103.8 | F6: =Projeções!F11 -> 2340472.1 | G6: =Projeções!G11 -> 2527709.9 | H6: =Projeções!H11 -> 2729926.7
A7: (−) Juros sobre a dívida nova | D7: =-D13 -> -1379700 | E7: =-E13 -> -1374562.8 | F7: =-F13 -> -1355343.1 | G7: =-G13 -> -1317094.1 | H7: =-H13 -> -1257345.4
A8: LAIR | D8: =D6+D7 -> 626877.62 | E8: =E6+E7 -> 792541.04 | F8: =F6+F7 -> 985129.01 | G8: =G6+G7 -> 1210615.8 | H8: =H6+H7 -> 1472581.3
A9: Impostos sobre o lucro | D9: =-MAX(0,D8)*Premissas!$C$29 -> -213138.39 | E9: =-MAX(0,E8)*Premissas!$C$29 -> -269463.95 | F9: =-MAX(0,F8)*Premissas!$C$29 -> -334943.86 | G9: =-MAX(0,G8)*Premissas!$C$29 -> -411609.37 | H9: =-MAX(0,H8)*Premissas!$C$29 -> -500677.64
A11: DÍVIDA E JUROS
A12: Saldo devedor inicial | D12: ='Sources & Uses'!C18 -> 9855000 | E12: =D19 -> 9855000 | F12: =E19 -> 9781611.3 | G12: =F19 -> 9580433.3 | H12: =G19 -> 9235196.8
A13: Juros do período (sobre saldo médio) | D13: =AVERAGE(D12,D19)*Premissas!$C$19 -> 1379700 | E13: =AVERAGE(E12,E19)*Premissas!$C$19 -> 1374562.8 | F13: =AVERAGE(F12,F19)*Premissas!$C$19 -> 1355343.1 | G13: =AVERAGE(G12,G19)*Premissas!$C$19 -> 1317094.1 | H13: =AVERAGE(H12,H19)*Premissas!$C$19 -> 1257345.4
A15: CAIXA DISPONÍVEL PARA CASH SWEEP
A16: EBITDA (Aba 3) | D16: =Projeções!D8 -> 2348122.7 | E16: =Projeções!E8 -> 2535972.6 | F16: =Projeções!F8 -> 2738850.4 | G16: =Projeções!G8 -> 2957958.4 | H16: =Projeções!H8 -> 3194595.1
A17: (−) Capex (Aba 3) | D17: =Projeções!D14 -> -597703.97 | E17: =Projeções!E14 -> -645520.29 | F17: =Projeções!F14 -> -697161.91 | G17: =Projeções!G14 -> -752934.86 | H17: =Projeções!H14 -> -813169.65
A18: (−) Variação de capital de giro (Aba 3) | D18: =Projeções!D16 -> -12649.819 | E18: =Projeções!E16 -> -13661.805 | F18: =Projeções!F16 -> -14754.749 | G18: =Projeções!G16 -> -15935.129 | H18: =Projeções!H16 -> -17209.94
A19: Saldo devedor final | D19: =D12-D25 -> 9855000 | E19: =E12-E25 -> 9781611.3 | F19: =F12-F25 -> 9580433.3 | G19: =G12-G25 -> 9235196.8 | H19: =H12-H25 -> 8726880.6
A20: (−) Juros pagos | D20: =-D13 -> -1379700 | E20: =-E13 -> -1374562.8 | F20: =-F13 -> -1355343.1 | G20: =-G13 -> -1317094.1 | H20: =-H13 -> -1257345.4
A21: (−) Impostos pagos | D21: =D9 -> -213138.39 | E21: =E9 -> -269463.95 | F21: =F9 -> -334943.86 | G21: =G9 -> -411609.37 | H21: =H9 -> -500677.64
A22: (−) Pagamento de arrendamento (Aba 3) | D22: =Projeções!D20 -> -187500 | E22: =Projeções!E20 -> -159375 | F22: =Projeções!F20 -> -135468.75 | G22: =Projeções!G20 -> -115148.44 | H22: =Projeções!H20 -> -97876.172
A23: Caixa disponível para cash sweep | D23: =D16+D17+D18+D20+D21+D22 -> -42569.437 | E23: =E16+E17+E18+E20+E21+E22 -> 73388.727 | F23: =F16+F17+F18+F20+F21+F22 -> 201177.97 | G23: =G16+G17+G18+G20+G21+G22 -> 345236.49 | H23: =H16+H17+H18+H20+H21+H22 -> 508316.25
A24: % destinado ao cash sweep | D24: =Premissas!$C$20 -> 1 | E24: =Premissas!$C$20 -> 1 | F24: =Premissas!$C$20 -> 1 | G24: =Premissas!$C$20 -> 1 | H24: =Premissas!$C$20 -> 1
A25: Amortização (cash sweep) | D25: =MIN(MAX(D23,0)*D24,D12) -> 0 | E25: =MIN(MAX(E23,0)*E24,E12) -> 73388.727 | F25: =MIN(MAX(F23,0)*F24,F12) -> 201177.97 | G25: =MIN(MAX(G23,0)*G24,G12) -> 345236.49 | H25: =MIN(MAX(H23,0)*H24,H12) -> 508316.25
A26: Alavancagem final (Dív. / EBITDA) | D26: =D19/D16 -> 4.1969697 | E26: =E19/E16 -> 3.857144 | F26: =F19/F16 -> 3.4979762 | G26: =G19/G16 -> 3.1221524 | H26: =H19/H16 -> 2.7317642

Sheet Saída
A1: FLEURY S.A. (FLRY3) — ABA 5: CÁLCULO DE SAÍDA (ANO 5)
A2: Valores em R$ mil
A4: SAÍDA NO ANO 5
A5: EBITDA do Ano 5 (Aba 3) | C5: =Projeções!H8 -> 3194595.1
A6: Múltiplo de saída (Aba 1) | C6: =Premissas!C11 -> 6.25
A7: Enterprise Value de saída | C7: =C5*C6 -> 19966219
A8: (−) Saldo devedor remanescente no Ano 5 (Aba 4) | C8: ='Debt Schedule'!H19 -> 8726880.6
A9: EQUITY VALUE DE SAÍDA | C9: =C7-C8 -> 11239339
A11: MÉTRICAS DE REFERÊNCIA
A12: Múltiplo de entrada (Aba 1) | C12: =Premissas!C10 -> 6.25
A13: Expansão/compressão de múltiplo | C13: =C6-C12 -> 0
A14: Crescimento do EBITDA vs. base (Aba 3) | C14: =C5/Premissas!C5-1 -> 0.45871921

Sheet Retorno
A1: FLEURY S.A. (FLRY3) — ABA 6: WATERFALL DE RETORNO DO SPONSOR
A2: Valores em R$ mil
A4: FLUXO DE CAIXA DO EQUITY DO SPONSOR
A5: Período | C5: Ano 0 | D5: Ano 1 | E5: Ano 2 | F5: Ano 3 | G5: Ano 4 | H5: Ano 5
A6: Fluxo de caixa do sponsor | C6: =-'Sources & Uses'!C19 -> -4106250 | D6: =0 -> 0 | E6: =0 -> 0 | F6: =0 -> 0 | G6: =0 -> 0 | H6: =Saída!C9 -> 11239339
A8: RETORNOS
A9: Equity investido pelo sponsor no Ano 0 (Aba 2) | C9: ='Sources & Uses'!C19 -> 4106250
A10: Equity Value de saída no Ano 5 (Aba 5) | C10: =Saída!C9 -> 11239339
A11: Ganho de capital | C11: =C10-C9 -> 7133088.6
A12: MOIC (múltiplo do capital investido) | C12: =C10/C9 -> 2.7371296
A13: TIR / IRR (5 anos) | C13: =IRR(C6:H6) -> 0.22309185
A14: Horizonte (Aba 1) | C14: =Premissas!C23 -> 5

Sheet Sensibilidade
A1: FLEURY S.A. (FLRY3) — ABA 7: SENSIBILIDADE DA TIR
A2: Múltiplo de saída (linhas) × Alavancagem inicial (colunas) | motor de cálculo replica a Aba 4 para cada alavancagem
B4: TIR — Saída (x) \ Alavanc. (x) | C4: 3.5 | D4: 4 | E4: 4.5 | F4: 5 | G4: 5.5
B5: 5.25 | C5: =IFERROR(RATE(Premissas!$C$23,0,-$C$19,Projeções!$H$8*$B5-$H$25),"n/d") -> 0.1271986 | D5: =IFERROR(RATE(Premissas!$C$23,0,-$C$29,Projeções!$H$8*$B5-$H$35),"n/d") -> 0.13318412 | E5: =IFERROR(RATE(Premissas!$C$23,0,-$C$39,Projeções!$H$8*$B5-$H$45),"n/d") -> 0.14396665 | F5: =IFERROR(RATE(Premissas!$C$23,0,-$C$49,Projeções!$H$8*$B5-$H$55),"n/d") -> 0.16646346 | G5: =IFERROR(RATE(Premissas!$C$23,0,-$C$59,Projeções!$H$8*$B5-$H$65),"n/d") -> 0.21527438
B6: 5.75 | C6: =IFERROR(RATE(Premissas!$C$23,0,-$C$19,Projeções!$H$8*$B6-$H$25),"n/d") -> 0.15700872 | D6: =IFERROR(RATE(Premissas!$C$23,0,-$C$29,Projeções!$H$8*$B6-$H$35),"n/d") -> 0.16820042 | E6: =IFERROR(RATE(Premissas!$C$23,0,-$C$39,Projeções!$H$8*$B6-$H$45),"n/d") -> 0.18616394 | F6: =IFERROR(RATE(Premissas!$C$23,0,-$C$49,Projeções!$H$8*$B6-$H$55),"n/d") -> 0.21884653 | G6: =IFERROR(RATE(Premissas!$C$23,0,-$C$59,Projeções!$H$8*$B6-$H$65),"n/d") -> 0.2835821
B7: 6.25 | C7: =IFERROR(RATE(Premissas!$C$23,0,-$C$19,Projeções!$H$8*$B7-$H$25),"n/d") -> 0.18402987 | D7: =IFERROR(RATE(Premissas!$C$23,0,-$C$29,Projeções!$H$8*$B7-$H$35),"n/d") -> 0.19946109 | E7: =IFERROR(RATE(Premissas!$C$23,0,-$C$39,Projeções!$H$8*$B7-$H$45),"n/d") -> 0.22309185 | F7: =IFERROR(RATE(Premissas!$C$23,0,-$C$49,Projeções!$H$8*$B7-$H$55),"n/d") -> 0.26351947 | G7: =IFERROR(RATE(Premissas!$C$23,0,-$C$59,Projeções!$H$8*$B7-$H$65),"n/d") -> 0.33984335
B8: 6.75 | C8: =IFERROR(RATE(Premissas!$C$23,0,-$C$19,Projeções!$H$8*$B8-$H$25),"n/d") -> 0.20878825 | D8: =IFERROR(RATE(Premissas!$C$23,0,-$C$29,Projeções!$H$8*$B8-$H$35),"n/d") -> 0.2277664 | E8: =IFERROR(RATE(Premissas!$C$23,0,-$C$39,Projeções!$H$8*$B8-$H$45),"n/d") -> 0.25603334 | F8: =IFERROR(RATE(Premissas!$C$23,0,-$C$49,Projeções!$H$8*$B8-$H$55),"n/d") -> 0.30264406 | G8: =IFERROR(RATE(Premissas!$C$23,0,-$C$59,Projeções!$H$8*$B8-$H$65),"n/d") -> 0.38798749
B9: 7.25 | C9: =IFERROR(RATE(Premissas!$C$23,0,-$C$19,Projeções!$H$8*$B9-$H$25),"n/d") -> 0.23167014 | D9: =IFERROR(RATE(Premissas!$C$23,0,-$C$29,Projeções!$H$8*$B9-$H$35),"n/d") -> 0.2536792 | E9: =IFERROR(RATE(Premissas!$C$23,0,-$C$39,Projeções!$H$8*$B9-$H$45),"n/d") -> 0.28584276 | F9: =IFERROR(RATE(Premissas!$C$23,0,-$C$49,Projeções!$H$8*$B9-$H$55),"n/d") -> 0.33756484 | G9: =IFERROR(RATE(Premissas!$C$23,0,-$C$59,Projeções!$H$8*$B9-$H$65),"n/d") -> 0.43025208
B12: Caso base do modelo: alavancagem 4,50x × múltiplo de saída 6,25x — célula central destacada em E7, que deve igualar a TIR da Aba 6.
A15: MOTOR DE CÁLCULO — CASCATA DE DÍVIDA POR NÍVEL DE ALAVANCAGEM
A17: Caso 1 — Alavancagem inicial | C17: =C$4 -> 3.5 | D17: Ano 1 | E17: Ano 2 | F17: Ano 3 | G17: Ano 4 | H17: Ano 5
A18: Dívida nova | C18: =C17*Premissas!$C$5 -> 7665000
A19: Equity do sponsor | C19: ='Sources & Uses'!$C$15-C18 -> 6296250
A20: Saldo devedor inicial | D20: =$C$18 -> 7665000 | E20: =D25 -> 7497473.7 | F20: =E25 -> 7195698.1 | G20: =F25 -> 6744008.1 | H20: =G25 -> 6123991
A21: Juros (saldo médio) | D21: =AVERAGE(D20,D25)*Premissas!$C$19 -> 1061373.2 | E21: =AVERAGE(E20,E25)*Premissas!$C$19 -> 1028522 | F21: =AVERAGE(F20,F25)*Premissas!$C$19 -> 975779.43 | G21: =AVERAGE(G20,G25)*Premissas!$C$19 -> 900759.94 | H21: =AVERAGE(H20,H25)*Premissas!$C$19 -> 800678.6
A22: Impostos | D22: =MAX(0,Projeções!D$11-D21)*Premissas!$C$29 -> 321369.52 | E22: =MAX(0,Projeções!E$11-E21)*Premissas!$C$29 -> 387117.81 | F22: =MAX(0,Projeções!F$11-F21)*Premissas!$C$29 -> 463995.52 | G22: =MAX(0,Projeções!G$11-G21)*Premissas!$C$29 -> 553162.99 | H22: =MAX(0,Projeções!H$11-H21)*Premissas!$C$29 -> 655944.35
A23: Caixa disponível p/ sweep | D23: =Projeções!D$8+Projeções!D$14+Projeções!D$16-D21-D22+Projeções!D$20 -> 167526.28 | E23: =Projeções!E$8+Projeções!E$14+Projeções!E$16-E21-E22+Projeções!E$20 -> 301775.63 | F23: =Projeções!F$8+Projeções!F$14+Projeções!F$16-F21-F22+Projeções!F$20 -> 451690.01 | G23: =Projeções!G$8+Projeções!G$14+Projeções!G$16-G21-G22+Projeções!G$20 -> 620017.04 | H23: =Projeções!H$8+Projeções!H$14+Projeções!H$16-H21-H22+Projeções!H$20 -> 809716.35
A24: Amortização (sweep) | D24: =MIN(MAX(D23,0)*Premissas!$C$20,D20) -> 167526.28 | E24: =MIN(MAX(E23,0)*Premissas!$C$20,E20) -> 301775.63 | F24: =MIN(MAX(F23,0)*Premissas!$C$20,F20) -> 451690.01 | G24: =MIN(MAX(G23,0)*Premissas!$C$20,G20) -> 620017.04 | H24: =MIN(MAX(H23,0)*Premissas!$C$20,H20) -> 809716.35
A25: Saldo devedor final | D25: =D20-D24 -> 7497473.7 | E25: =E20-E24 -> 7195698.1 | F25: =F20-F24 -> 6744008.1 | G25: =G20-G24 -> 6123991 | H25: =H20-H24 -> 5314274.7
A27: Caso 2 — Alavancagem inicial | C27: =D$4 -> 4 | D27: Ano 1 | E27: Ano 2 | F27: Ano 3 | G27: Ano 4 | H27: Ano 5
A28: Dívida nova | C28: =C27*Premissas!$C$5 -> 8760000
A29: Equity do sponsor | C29: ='Sources & Uses'!$C$15-C28 -> 5201250
A30: Saldo devedor inicial | D30: =$C$28 -> 8760000 | E30: =D35 -> 8698552.6 | F30: =E35 -> 8513132.2 | G30: =F35 -> 8189069.5 | H30: =G35 -> 7709043.8
A31: Juros (saldo médio) | D31: =AVERAGE(D30,D35)*Premissas!$C$19 -> 1222098.7 | E31: =AVERAGE(E30,E35)*Premissas!$C$19 -> 1204817.9 | F31: =AVERAGE(F30,F35)*Premissas!$C$19 -> 1169154.1 | G31: =AVERAGE(G30,G35)*Premissas!$C$19 -> 1112867.9 | H31: =AVERAGE(H30,H35)*Premissas!$C$19 -> 1033334.7
A32: Impostos | D32: =MAX(0,Projeções!D$11-D31)*Premissas!$C$29 -> 266722.84 | E32: =MAX(0,Projeções!E$11-E31)*Premissas!$C$29 -> 327177.2 | F32: =MAX(0,Projeções!F$11-F31)*Premissas!$C$29 -> 398248.12 | G32: =MAX(0,Projeções!G$11-G31)*Premissas!$C$29 -> 481046.27 | H32: =MAX(0,Projeções!H$11-H31)*Premissas!$C$29 -> 576841.28
A33: Caixa disponível p/ sweep | D33: =Projeções!D$8+Projeções!D$14+Projeções!D$16-D31-D32+Projeções!D$20 -> 61447.435 | E33: =Projeções!E$8+Projeções!E$14+Projeções!E$16-E31-E32+Projeções!E$20 -> 185420.33 | F33: =Projeções!F$8+Projeções!F$14+Projeções!F$16-F31-F32+Projeções!F$20 -> 324062.71 | G33: =Projeções!G$8+Projeções!G$14+Projeções!G$16-G31-G32+Projeções!G$20 -> 480025.77 | H33: =Projeções!H$8+Projeções!H$14+Projeções!H$16-H31-H32+Projeções!H$20 -> 656163.33
A34: Amortização (sweep) | D34: =MIN(MAX(D33,0)*Premissas!$C$20,D30) -> 61447.435 | E34: =MIN(MAX(E33,0)*Premissas!$C$20,E30) -> 185420.33 | F34: =MIN(MAX(F33,0)*Premissas!$C$20,F30) -> 324062.71 | G34: =MIN(MAX(G33,0)*Premissas!$C$20,G30) -> 480025.77 | H34: =MIN(MAX(H33,0)*Premissas!$C$20,H30) -> 656163.33
A35: Saldo devedor final | D35: =D30-D34 -> 8698552.6 | E35: =E30-E34 -> 8513132.2 | F35: =F30-F34 -> 8189069.5 | G35: =G30-G34 -> 7709043.8 | H35: =H30-H34 -> 7052880.4
A37: Caso 3 — Alavancagem inicial | C37: =E$4 -> 4.5 | D37: Ano 1 | E37: Ano 2 | F37: Ano 3 | G37: Ano 4 | H37: Ano 5
A38: Dívida nova | C38: =C37*Premissas!$C$5 -> 9855000
A39: Equity do sponsor | C39: ='Sources & Uses'!$C$15-C38 -> 4106250
A40: Saldo devedor inicial | D40: =$C$38 -> 9855000 | E40: =D45 -> 9855000 | F40: =E45 -> 9781611.3 | G40: =F45 -> 9580433.3 | H40: =G45 -> 9235196.8
A41: Juros (saldo médio) | D41: =AVERAGE(D40,D45)*Premissas!$C$19 -> 1379700 | E41: =AVERAGE(E40,E45)*Premissas!$C$19 -> 1374562.8 | F41: =AVERAGE(F40,F45)*Premissas!$C$19 -> 1355343.1 | G41: =AVERAGE(G40,G45)*Premissas!$C$19 -> 1317094.1 | H41: =AVERAGE(H40,H45)*Premissas!$C$19 -> 1257345.4
A42: Impostos | D42: =MAX(0,Projeções!D$11-D41)*Premissas!$C$29 -> 213138.39 | E42: =MAX(0,Projeções!E$11-E41)*Premissas!$C$29 -> 269463.95 | F42: =MAX(0,Projeções!F$11-F41)*Premissas!$C$29 -> 334943.86 | G42: =MAX(0,Projeções!G$11-G41)*Premissas!$C$29 -> 411609.37 | H42: =MAX(0,Projeções!H$11-H41)*Premissas!$C$29 -> 500677.64
A43: Caixa disponível p/ sweep | D43: =Projeções!D$8+Projeções!D$14+Projeções!D$16-D41-D42+Projeções!D$20 -> -42569.437 | E43: =Projeções!E$8+Projeções!E$14+Projeções!E$16-E41-E42+Projeções!E$20 -> 73388.727 | F43: =Projeções!F$8+Projeções!F$14+Projeções!F$16-F41-F42+Projeções!F$20 -> 201177.97 | G43: =Projeções!G$8+Projeções!G$14+Projeções!G$16-G41-G42+Projeções!G$20 -> 345236.49 | H43: =Projeções!H$8+Projeções!H$14+Projeções!H$16-H41-H42+Projeções!H$20 -> 508316.25
A44: Amortização (sweep) | D44: =MIN(MAX(D43,0)*Premissas!$C$20,D40) -> 0 | E44: =MIN(MAX(E43,0)*Premissas!$C$20,E40) -> 73388.727 | F44: =MIN(MAX(F43,0)*Premissas!$C$20,F40) -> 201177.97 | G44: =MIN(MAX(G43,0)*Premissas!$C$20,G40) -> 345236.49 | H44: =MIN(MAX(H43,0)*Premissas!$C$20,H40) -> 508316.25
A45: Saldo devedor final | D45: =D40-D44 -> 9855000 | E45: =E40-E44 -> 9781611.3 | F45: =F40-F44 -> 9580433.3 | G45: =G40-G44 -> 9235196.8 | H45: =H40-H44 -> 8726880.6
A47: Caso 4 — Alavancagem inicial | C47: =F$4 -> 5 | D47: Ano 1 | E47: Ano 2 | F47: Ano 3 | G47: Ano 4 | H47: Ano 5
A48: Dívida nova | C48: =C47*Premissas!$C$5 -> 10950000
A49: Equity do sponsor | C49: ='Sources & Uses'!$C$15-C48 -> 3011250
...
